<?xml version="1.0"?>
<robot name="robot_manipulator">

<material name="blue">
    <color rgba="0 0 0.8 1"/>
</material>

<material name="red">
    <color rgba="0.8 0 0 1"/>
</material>

<material name="green">
    <color rgba="0 0.8 0 1"/>
</material>

<material name="yellow">
    <color rgba="1 1 0 1"/>
</material>

<material name="cyan">
    <color rgba="0 1 1 1"/>
</material>

<link name="world"/>
<joint name="fixed_joint" type="fixed">
    <origin rpy="0 0 0" xyz="0 0 0"/>
    <parent link="world"/>
    <child link="base_link"/>
</joint>

<link name="base_link">
    <visual>
        <geometry>
            <cylinder radius="0.2" length="0.4"/>
        </geometry>
        <origin xyz="0 0 0" rpy="0 0 0"/>
        <material name="green"/>
    </visual>
</link>

<joint name="joint_1" type="revolute">
    <origin rpy="0 0 0" xyz="0 0 0.1"/>
    <parent link="base_link"/>
    <child link="link_1"/>
    <axis xyz="0.0 0.0 1.0"/>
    <limit lower="-3.14" upper="3.14" effort="300.0" velocity="2.0"/>   
</joint>

<link name="link_1">
    <visual>
        <geometry>
            <cylinder radius="0.15" length="0.6"/>
        </geometry>
        <origin xyz="0 0 0.3" rpy="0 0 0"/>
        <material name="yellow"/>
    </visual>
</link>

<joint name="joint_2" type="revolute">
    <origin rpy="0 -1.570796 0" xyz="-0.15 0 0.5"/>
    <parent link="link_1"/>
    <child link="link_2"/>
    <axis xyz="0.0 0.0 1.0"/>
    <limit lower="-3.14" upper="3.14" effort="300.0" velocity="2.0"/>   
</joint>

<link name="link_2">
    <visual>
        <geometry>
            <cylinder radius="0.1" length="1"/>
        </geometry>
        <origin xyz="0.3 0 0.1" rpy="0 1.570796 0"/>
        <material name="red"/>
    </visual>
</link>

<joint name="joint_3" type="revolute">
    <origin rpy="0 0 0" xyz="0.7 0 0"/>
    <parent link="link_2"/>
    <child link="link_3"/>
    <axis xyz="0.0 0.0 1.0"/>
    <limit lower="-3.14" upper="3.14" effort="300.0" velocity="2.0"/>   
</joint>

<link name="link_3">
    <visual>
        <geometry>
            <cylinder radius="0.1" length="1"/>
        </geometry>
        <origin xyz="0.4 0 -0.1" rpy="0 1.570796 0"/>
        <material name="yellow"/>
    </visual>
</link>

<joint name="joint_4" type="revolute">
    <origin rpy="0 0 0" xyz="1 0 -0.1"/>
    <parent link="link_3"/>
    <child link="link_4"/>
    <axis xyz="0 0 1"/>
    <limit lower="-3.14" upper="3.14" effort="300.0" velocity="2.0"/>   
</joint>

<link name="link_4">
    <visual>
        <geometry>
            <cylinder radius="0.1" length="0.4"/>
        </geometry>
        <origin xyz="0 0 0.1" rpy="0 0 0"/>
        <material name="blue"/>
    </visual>
</link>


<joint name="joint_5" type="revolute">
    <origin rpy="0 1.570796 0" xyz="0 0 0.4"/>
    <parent link="link_4"/>
    <child link="link_5"/>
    <axis xyz="0 0 1"/>
    <limit lower="-3.14" upper="3.14" effort="300.0" velocity="2.0"/>   
</joint>

<link name="link_5">
    <visual>
        <geometry>
            <cylinder radius="0.1" length="0.4"/>
        </geometry>
        <origin xyz="0 0 0.1" rpy="0 0 0"/>
        <material name="cyan"/>
    </visual>
</link>

<joint name="joint_6" type="revolute">
    <origin rpy="-1.570796 0 0" xyz="0 0 0.4"/>
    <parent link="link_5"/>
    <child link="link_6"/>
    <axis xyz="0 0 1"/>
    <limit lower="-3.14" upper="3.14" effort="300.0" velocity="2.0"/>   
</joint>

<link name="link_6">
    <visual>
        <geometry>
            <cylinder radius="0.1" length="0.3"/>
        </geometry>
        <origin xyz="0 0 0.1" rpy="0 0 0"/>
        <material name="red"/>
    </visual>
</link>


<joint name="joint_7" type="prismatic">
    <origin rpy="0 0 0" xyz="0.08 0 0.25"/>
    <parent link="link_6"/>
    <child link="link_7"/>
    <axis xyz="1 0 0"/>
    <limit lower="-0.06" upper="0" effort="300.0" velocity="2.0"/>   
</joint>

<link name="link_7">
    <visual>
        <geometry>
            <box size="0.03 0.06 0.5"/>
        </geometry>
        <origin xyz="0 0 0.075" rpy="0 0 0"/>
        <material name="yellow"/>
    </visual>
</link>

<joint name="joint_8" type="prismatic">
    <origin rpy="0 0 0" xyz="-0.08 0 0.25"/>
    <parent link="link_6"/>
    <child link="link_8"/>
    <axis xyz="1 0 0"/>
    <limit lower="0.06" upper="0" effort="300.0" velocity="2.0"/>   
</joint>

<link name="link_8">
    <visual>
        <geometry>
            <box size="0.03 0.06 0.5"/>
        </geometry>
        <origin xyz="0 0 0.075" rpy="0 0 0"/>
        <material name="yellow"/>
    </visual>
</link>
</robot>