<?xml version="1.0" ?>
<robot name="moving_robotic_arm">
<material name="blue">
    <color rgba="0 0 0.8 1"/>
</material>

<material name="red">
    <color rgba="0.8 0 0 1"/>
</material>

<material name="green">
    <color rgba="0 0.8 0 1"/>
</material>

<material name="yellow">
    <color rgba="1 1 0 1"/>
</material>

<material name="cyan">
    <color rgba="0 1 1 1"/>
</material>

  <material name="Black">
    <color rgba="0.0 0.0 0.0 1.0"/>
  </material>
 
  <material name="White">
    <color rgba="1.0 1.0 1.0 1.0"/>
  </material>

  <material name="DarkGray">
    <color rgba="0.66 0.66 0.66 1.0"/>
  </material>

  <link name="base_footprint">
    <inertial>
      <mass value="0.0001"/>
      <origin xyz="0 0 0"/>
      <inertia ixx="0.0001" ixy="0.0" ixz="0.0" iyy="0.0001" iyz="0.0" izz="0.0001"/>
    </inertial>
    <visual>
      <origin rpy="0 0 0" xyz="0 0 0"/>
      <geometry>
        <box size="0.001 0.001 0.001"/>
      </geometry>
    </visual>
  </link>

    <joint name="base_footprint_joint" type="fixed">
    <origin rpy="0 0 0" xyz="0 0 0.04"/>
    <parent link="base_footprint"/>
    <child link="base_link"/>
  </joint>

  <link name="base_link">
    <inertial>
      <mass value="5"/>
      <origin xyz="0 0 0"/>
      <!--The 3x3 rotational inertia matrix. -->
      <inertia ixx="0.0282916666667" ixy="0" ixz="0" iyy="0.0282916666667" iyz="0" izz="0.05625"/>
    </inertial>
    <visual>
      <origin rpy="0 0 0" xyz="0 0 0"/>
      <geometry>
        <cylinder length="0.2" radius="0.30"/>
      </geometry>
      <material name="White"/>
    </visual>
    <collision>
      <origin rpy="0 0 0 " xyz="0 0 0"/>
      <geometry>
        <cylinder length="0.02" radius="0.15"/>
      </geometry>
    </collision>
  </link>

 <link name="front_right_wheel">
    <visual>
      <origin rpy="1.57079632679 0  0 " xyz="0 0 0"/>
      <geometry>
        <cylinder length="0.04" radius="0.15"/>
      </geometry>
      <material name="red"/>
    </visual>
    <collision>
      <origin rpy="1.57079632679 0 0 " xyz="0 0 0"/>
      <geometry>
        <cylinder length="0.04" radius="0.15"/>
      </geometry>
    </collision>
    <inertial>
      <mass value="2.5"/>
      <origin xyz="0 0 0"/>
      <inertia ixx="0.00108333333333" ixy="0" ixz="0" iyy="0.00108333333333" iyz="0" izz="0.002"/>
    </inertial>
  </link>

    <joint name="front_right_wheel_joint" type="continuous">
    <parent link="base_link"/>
    <child link="front_right_wheel"/>
    <origin rpy="0 0 0" xyz="0.0 0.32 0.0"/>
    <axis rpy="0  0" xyz="0 1 0"/>
    <limit effort="100" velocity="100"/>
    <joint_properties damping="0.0" friction="0.0"/>
  </joint>

  <link name="front_left_wheel">
    <visual>
      <origin rpy="1.57079632679 0  0 " xyz="0 0 0"/>
      <geometry>
        <cylinder length="0.04" radius="0.15"/>
      </geometry>
      <material name="red"/>
    </visual>
    <collision>
      <origin rpy="1.57079632679 0 0 " xyz="0 0 0"/>
      <geometry>
        <cylinder length="0.04" radius="0.15"/>
      </geometry>
    </collision>
    <inertial>
      <mass value="2.5"/>
      <origin xyz="0 0 0"/>
      <inertia ixx="0.00108333333333" ixy="0" ixz="0" iyy="0.00108333333333" iyz="0" izz="0.002"/>
    </inertial>
  </link>

  <joint name="front_left_wheel_joint" type="continuous">
    <parent link="base_link"/>
    <child link="front_left_wheel"/>
    <origin rpy="0 0 0" xyz="0.0 -0.32 0.0"/>
    <axis rpy="0  0" xyz="0 1 0"/>
    <limit effort="100" velocity="100"/>
    <joint_properties damping="0.0" friction="0.0"/>
  </joint>

  <!--Caster front  -->
  <link name="caster_front_link">
    <visual>
      <origin rpy="1.57079632679 0 0" xyz="0 0.02 0"/>
      <geometry>
        <sphere radius="0.025"/>
      </geometry>
      <material name="Black"/>
    </visual>
    <collision>
      <geometry>
        <sphere radius="0.050"/>
      </geometry>
      <origin rpy="1.57079632679 0 0" xyz="0 0.02 0"/>
    </collision>
    <inertial>
      <mass value="0.5"/>
      <origin xyz="0 0 0"/>
      <inertia ixx="0.001" ixy="0.0" ixz="0.0" iyy="0.001" iyz="0.0" izz="0.001"/>
    </inertial>
  </link>
  <joint name="caster_front_joint" type="fixed">
    <parent link="base_link"/>
    <child link="caster_front_link"/>
    <origin rpy="-1.57079632679 0 0" xyz="0.28 0.0 -0.1"/>
  </joint>

<joint name="fixed_joint" type="fixed">
    <origin rpy="0 0 0" xyz="0 0 0.2"/>
    <parent link="base_link"/>
    <child link="arm_base"/>
</joint>

<link name="arm_base">
    <visual>
        <geometry>
            <cylinder radius="0.2" length="0.4"/>
        </geometry>
        <origin xyz="0 0 0" rpy="0 0 0"/>
        <material name="green"/>
    </visual>
</link>

<joint name="joint_1" type="revolute">
    <origin rpy="0 0 0" xyz="0 0 0"/>
    <parent link="arm_base"/>
    <child link="link_1"/>
    <axis xyz="0.0 0.0 1.0"/>
    <limit lower="-3.14" upper="3.14" effort="300.0" velocity="2.0"/>   
</joint>

<link name="link_1">
    <visual>
        <geometry>
            <cylinder radius="0.15" length="0.3"/>
        </geometry>
        <origin xyz="0 0 0.3" rpy="0 0 0"/>
        <material name="yellow"/>
    </visual>
</link>
<joint name="joint_2" type="revolute">
    <origin rpy="0 -1.570796 0" xyz="-0.1 0 0.3"/>
    <parent link="link_1"/>
    <child link="link_2"/>
    <axis xyz="0.0 0.0 1.0"/>
    <limit lower="-3.14" upper="3.14" effort="300.0" velocity="2.0"/>   
</joint>

<link name="link_2">
    <visual>
        <geometry>
            <cylinder radius="0.1" length="0.5"/>
        </geometry>
        <origin xyz="0.3 0 0.1" rpy="0 1.570796 0"/>
        <material name="red"/>
    </visual>
</link>

<joint name="joint_3" type="revolute">
    <origin rpy="-1.570796 0 0" xyz="0.6 0.1 0.1"/>
    <parent link="link_2"/>
    <child link="link_3"/>
    <axis xyz="0 0 1"/>
    <limit lower="-3.14" upper="3.14" effort="300.0" velocity="2.0"/>   
</joint>

<link name="link_3">
    <visual>
        <geometry>
            <cylinder radius="0.1" length="0.3"/>
        </geometry>
        <origin xyz="0 0 0.1" rpy="0 0 0"/>
        <material name="red"/>
    </visual>
</link>
<joint name="joint_4" type="prismatic">
    <origin rpy="0 0 0" xyz="0.08 0 0.25"/>
    <parent link="link_3"/>
    <child link="link_4"/>
    <axis xyz="1 0 0"/>
    <limit lower="-0.06" upper="0" effort="300.0" velocity="2.0"/>   
</joint>

<link name="link_4">
    <visual>
        <geometry>
            <box size="0.03 0.06 0.5"/>
        </geometry>
        <origin xyz="0 0 0.075" rpy="0 0 0"/>
        <material name="yellow"/>
    </visual>
</link>

<joint name="joint_5" type="prismatic">
    <origin rpy="0 0 0" xyz="-0.08 0 0.25"/>
    <parent link="link_3"/>
    <child link="link_5"/>
    <axis xyz="1 0 0"/>
    <limit lower="0.06" upper="0" effort="300.0" velocity="2.0"/>   
</joint>

<link name="link_5">
    <visual>
        <geometry>
            <box size="0.03 0.06 0.5"/>
        </geometry>
        <origin xyz="0 0 0.075" rpy="0 0 0"/>
        <material name="yellow"/>
    </visual>
</link>
</robot>
